<?xml version="1.0"?>
<robot name="VoiceVidManipulator">
   <material name="black">
    <color rgba="0.0 0.0 0.0 1.0"/>
  </material>
  <material name="white">
    <color rgba="1.0 1.0 1.0 1.0"/>
  </material>
  <material name="red">
    <color rgba="0.8 0.0 0.0 1.0"/>
  </material>
  <material name="blue">
    <color rgba="0.0 0.0 0.8 1.0"/>
  </material>
  <material name="green">
    <color rgba="0.0 0.8 0.0 1.0"/>
  </material>
  <material name="grey">
    <color rgba="0.5 0.5 0.5 1.0"/>
  </material>
  <material name="orange">
    <color rgba="1.0 0.4235294117647059 0.0392156862745098 1.0"/>
  </material>
  <material name="brown">
    <color rgba="0.8705882352941177 0.8117647058823529 0.7647058823529411 1.0"/>
  </material>
  <!-- World -->
  <gazebo reference="world"/>
  <!-- Link1 -->
  <RefLink ref="link1"/>
  <!-- Link2 -->
  <RefLink ref="link2"/>
  <!-- Link3 -->
  <RefLink ref="link3"/>
  <!-- Link4 -->
  <RefLink ref="link4"/>
  <!-- Link5 -->
  <RefLink ref="link5"/>
  <!-- gripper_link -->
  <RefLink ref="gripper_link"/>
  <!-- gripper_link_sub -->
  <RefLink ref="gripper_link_sub"/>
  <!-- end effector link -->
  <gazebo reference="end_effector_link">
    <material>Gazebo/Red</material>
  </gazebo>
  <!-- ros_control plugin -->
  <gazebo>
    <plugin filename="libgazebo_ros2_control.so" name="gazebo_ros2_control">
      <!-- <controlPeriod>0.001</controlPeriod>
      <robotSimType>gazebo_ros_control/DefaultRobotHWSim</robotSimType>
      <legacyModeNS>true</legacyModeNS> -->
      <!-- <xacro:property name="config_path" value="config/vvm.yaml" />
      <parameters>${arg config_path}</parameters> -->
      <parameters>/home/yash/vvm_ws/install/simulation_vvm/share/simulation_vvm/config/vvm.yaml</parameters>
      <robot_param>robot_description</robot_param>
      <robot_param_node>robot_state_publisher</robot_param_node>
      <controller_manager_name>controller_manager</controller_manager_name>
    </plugin>
  </gazebo>
  <gazebo>
    <!--loading_plugin:mimic_joints_works_in_gazebo_now-->
    <plugin filename="libroboticsgroup_gazebo_mimic_joint_plugin.so" name="gazebo_gripper_ros2_control">
      <joint>gripper</joint>
      <mimicJoint>gripper_sub</mimicJoint>
      <multiplier>1.0</multiplier>
      <offset>0.0</offset>
    </plugin>
  </gazebo>
  <ros2_control name="GazeboSystem" type="system">
    <hardware>
      <plugin>gazebo_ros2_control/GazeboSystem</plugin>
    </hardware>
    <joint name="joint1">
      <command_interface name="position"/>
      <state_interface name="position">
        <param name="initial_value">0.0</param>
      </state_interface>
      <state_interface name="velocity"/>
      <state_interface name="effort"/>
    </joint>
    <joint name="joint2">
      <command_interface name="position"/>
      <state_interface name="position">
        <param name="initial_value">0.0</param>
      </state_interface>
      <state_interface name="velocity"/>
      <state_interface name="effort"/>
    </joint>
    <joint name="joint3">
      <command_interface name="position"/>
      <state_interface name="position">
        <param name="initial_value">0.0</param>
      </state_interface>
      <state_interface name="velocity"/>
      <state_interface name="effort"/>
    </joint>
    <joint name="joint4">
      <command_interface name="position"/>
      <state_interface name="position">
        <param name="initial_value">0.7</param>
      </state_interface>
      <state_interface name="velocity"/>
      <state_interface name="effort"/>
    </joint>
    <joint name="gripper">
      <command_interface name="position"/>
      <state_interface name="position">
        <param name="initial_value">0.12</param>
      </state_interface>
      <state_interface name="velocity"/>
      <state_interface name="effort"/>
    </joint>
    <joint name="gripper_sub">
      <command_interface name="position"/>
      <state_interface name="position">
        <param name="initial_value">0.12</param>
      </state_interface>
      <state_interface name="velocity"/>
      <state_interface name="effort"/>
    </joint>
  </ros2_control>
  <!-- camera -->
  <gazebo reference="camera_link">
    <sensor name="intel_realsense_r200" type="camera">
      <update_rate>30.0</update_rate>
      <camera name="head">
        <horizontal_fov>1.02974</horizontal_fov>
        <image>
          <width>1920</width>
          <height>1080</height>
          <format>R8G8B8</format>
        </image>
        <clip>
          <near>0.02</near>
          <far>300</far>
        </clip>
        <noise>
          <type>gaussian</type>
          <!-- Noise is sampled independently per pixel on each frame.
               That pixel's noise value is added to each of its color
               channels, which at that point lie in the range [0,1]. -->
          <mean>0.0</mean>
          <stddev>0.007</stddev>
        </noise>
      </camera>
      <plugin filename="libgazebo_ros_camera.so" name="camera_controller">
        <!-- <alwaysOn>true</alwaysOn>
        <updateRate>0.0</updateRate>
        <cameraName>camera/color</cameraName>
        <imageTopicName>image_raw</imageTopicName>
        <cameraInfoTopicName>camera_info</cameraInfoTopicName> -->
        <frameName>camera_link</frameName>
        <min_depth>0.1</min_depth>
        <max_depth>500</max_depth>
        <!-- <hackBaseline>0.07</hackBaseline>
        <distortionK1>0.0</distortionK1>
        <distortionK2>0.0</distortionK2>
        <distortionK3>0.0</distortionK3>
        <distortionT1>0.0</distortionT1>
        <distortionT2>0.0</distortionT2> -->
      </plugin>
    </sensor>
  </gazebo>
  <transmission name="tran1">
    <type>transmission_interface/SimpleTransmission</type>
    <joint name="joint1">
      <hardwareInterface>hardware_interface/PositionJointInterface</hardwareInterface>
    </joint>
    <actuator name="motor1">
      <mechanicalReduction>1</mechanicalReduction>
    </actuator>
  </transmission>
  <transmission name="tran2">
    <type>transmission_interface/SimpleTransmission</type>
    <joint name="joint2">
      <hardwareInterface>hardware_interface/PositionJointInterface</hardwareInterface>
    </joint>
    <actuator name="motor2">
      <mechanicalReduction>1</mechanicalReduction>
    </actuator>
  </transmission>
  <transmission name="tran3">
    <type>transmission_interface/SimpleTransmission</type>
    <joint name="joint3">
      <hardwareInterface>hardware_interface/PositionJointInterface</hardwareInterface>
    </joint>
    <actuator name="motor3">
      <mechanicalReduction>1</mechanicalReduction>
    </actuator>
  </transmission>
  <transmission name="tran4">
    <type>transmission_interface/SimpleTransmission</type>
    <joint name="joint4">
      <hardwareInterface>hardware_interface/PositionJointInterface</hardwareInterface>
    </joint>
    <actuator name="motor4">
      <mechanicalReduction>1</mechanicalReduction>
    </actuator>
  </transmission>
  <transmission name="tran5">
    <type>transmission_interface/SimpleTransmission</type>
    <joint name="gripper">
      <hardwareInterface>hardware_interface/EffortJointInterface</hardwareInterface>
    </joint>
    <actuator name="motor5">
      <mechanicalReduction>1</mechanicalReduction>
    </actuator>
  </transmission>
  <transmission name="tran6">
    <type>transmission_interface/SimpleTransmission</type>
    <joint name="gripper_sub">
      <hardwareInterface>hardware_interface/EffortJointInterface</hardwareInterface>
    </joint>
    <actuator name="motor6">
      <mechanicalReduction>1</mechanicalReduction>
    </actuator>
  </transmission>
  
  <!-- Link definitions -->
  <link name='world'/>
  <joint name="dummy_joint" type="fixed">
    <parent link="world"/>
    <child link="link1"/>
  </joint>
  <link name="link1">
    <inertial>
      <origin xyz="0.000309 0 -0.000122" rpy="0 0 0"/>
      <mass value="0.07912"/>
      <inertia ixx="1.25052e-05" ixy="0" ixz="-1.78552e-07" iyy="2.18984e-05" iyz="0" izz="1.92674e-05"/>
    </inertial>
    <collision name="link1_collision">
      <origin xyz="0 0 0" rpy="0 0 0"/>
      <geometry>
        <mesh filename="package://simulation_vvm/meshes/chain_link1.stl" scale="0.001 0.001 0.001"/>
      </geometry>
    </collision>
    <visual name="link1_visual">
      <origin xyz="0 0 0" rpy="0 0 0"/>
      <geometry>
        <mesh filename="package://simulation_vvm/meshes/chain_link1.stl" scale="0.001 0.001 0.001"/>
      </geometry>
    </visual>
  </link>

  <link name="link2">
    <inertial>
      <origin xyz="-0.000302 0.00054 0.047433" rpy="0 0 0"/>
      <mass value="0.0984068"/>
      <inertia ixx="3.45434e-05" ixy="-1.60311e-08" ixz="-3.83752e-07" iyy="3.26893e-05" iyz="2.85119e-08" izz="1.88503e-05"/>
    </inertial>
    <collision name="link2_collision">
      <origin xyz="0 0 0.019" rpy="0 0 0"/>
      <geometry>
        <mesh filename="package://simulation_vvm/meshes/chain_link2.stl" scale="0.001 0.001 0.001"/>
      </geometry>
    </collision>
    <visual name="link2_visual">
      <origin xyz="0 0 0.019" rpy="0 0 0"/>
      <geometry>
        <mesh filename="package://simulation_vvm/meshes/chain_link2.stl" scale="0.001 0.001 0.001"/>
      </geometry>
    </visual>
  </link>

  <link name="link3">
    <inertial>
      <origin xyz="0.010308 0.000377 0.101702" rpy="0 0 0"/>
      <mass value="0.138509"/>
      <inertia ixx="0.000330554" ixy="-9.7941e-08" ixz="-3.85057e-05" iyy="0.000342904" iyz="-1.57175e-06" izz="6.03465e-05"/>
    </inertial>
    <collision name="link3_collision">
      <origin xyz="0 0 0" rpy="0 0 0"/>
      <geometry>
        <mesh filename="package://simulation_vvm/meshes/chain_link3.stl" scale="0.001 0.001 0.001"/>
      </geometry>
    </collision>
    <visual name="link3_visual">
      <origin xyz="0 0 0" rpy="0 0 0"/>
      <geometry>
        <mesh filename="package://simulation_vvm/meshes/chain_link3.stl" scale="0.001 0.001 0.001"/>
      </geometry>
    </visual>
  </link>

  <link name="link4">
    <inertial>
      <origin xyz="0.09091 0.000389 0.000224" rpy="0 0 0"/>
      <mass value="0.132746"/>
      <inertia ixx="3.06542e-05" ixy="-1.27642e-06" ixz="-2.68744e-07" iyy="0.000242303" iyz="1.15595e-08" izz="0.000251551"/>
    </inertial>
    <collision name="link4_collision">
      <origin xyz="0 0 0" rpy="0 0 0"/>
      <geometry>
        <mesh filename="package://simulation_vvm/meshes/chain_link4.stl" scale="0.001 0.001 0.001"/>
      </geometry>
    </collision>
    <visual name="link4_visual">
      <origin xyz="0 0 0" rpy="0 0 0"/>
      <geometry>
        <mesh filename="package://simulation_vvm/meshes/chain_link4.stl" scale="0.001 0.001 0.001"/>
      </geometry>
    </visual>
  </link>

  <link name="link5">
    <inertial>
      <origin xyz="0.044774 0 0.008852" rpy="0 0 0"/>
      <mass value="0.144276"/>
      <inertia ixx="0.00108095" ixy="2.99238e-11" ixz="-2.9172e-07" iyy="0.0010827" iyz="-3.26124e-12" izz="0.00109977"/>
    </inertial>
    <collision name="link5_collision">
      <origin xyz="0 0 0" rpy="0 0 0"/>
      <geometry>
        <mesh filename="package://simulation_vvm/meshes/chain_link5.stl" scale="0.001 0.001 0.001"/>
      </geometry>
    </collision>
    <visual name="link5_visual">
      <origin xyz="0 0 0" rpy="0 0 0"/>
      <geometry>
        <mesh filename="package://simulation_vvm/meshes/chain_link5.stl" scale="0.001 0.001 0.001"/>
      </geometry>
    </visual>
    <visual name="link5_fixed_joint_lump__end_effector_link_visual_1">
      <origin xyz="0.126 0 0" rpy="0 0 0"/>
      <geometry>
        <box size="0.01 0.01 0.01"/>
      </geometry>
    </visual>
  </link>

  <link name="gripper_link">
    <inertial>
      <origin xyz="0 0 0" rpy="0 0 0"/>
      <mass value="0.001"/>
      <inertia ixx="0.001" ixy="0" ixz="0" iyy="0.001" iyz="0" izz="0.001"/>
    </inertial>
    <collision name="gripper_link_collision">
      <origin xyz="0 0 0" rpy="0 0 0"/>
      <geometry>
        <mesh filename="package://simulation_vvm/meshes/chain_link_grip_l.stl" scale="0.001 0.001 0.001"/>
      </geometry>
    </collision>
    <visual name="gripper_link_visual">
      <origin xyz="0 0 0" rpy="0 0 0"/>
      <geometry>
        <mesh filename="package://simulation_vvm/meshes/chain_link_grip_l.stl" scale="0.001 0.001 0.001"/>
      </geometry>
    </visual>
  </link>

  <link name="gripper_link_sub">
    <inertial>
      <origin xyz="0 0 0" rpy="0 0 0"/>
      <mass value="0.001"/>
      <inertia ixx="0.001" ixy="0" ixz="0" iyy="0.001" iyz="0" izz="0.001"/>
    </inertial>
    <collision name="gripper_link_sub_collision">
      <origin xyz="0 0 0" rpy="0 0 0"/>
      <geometry>
        <mesh filename="package://simulation_vvm/meshes/chain_link_grip_r.stl" scale="0.001 0.001 0.001"/>
      </geometry>
    </collision>
    <visual name="gripper_link_sub_visual">
      <origin xyz="0 0 0" rpy="0 0 0"/>
      <geometry>
        <mesh filename="package://simulation_vvm/meshes/chain_link_grip_r.stl" scale="0.001 0.001 0.001"/>
      </geometry>
    </visual>
  </link>

  <link name="camera_link">
    <inertial>
      <origin xyz="0 0 0" rpy="0 0 0"/>
      <mass value="0.001"/>
      <inertia ixx="0.001" ixy="0" ixz="0" iyy="0.001" iyz="0" izz="0.001"/>
    </inertial>
    <collision name="camera_link_collision">
      <origin xyz="0 0 0" rpy="0 0 0"/>
      <geometry>
        <mesh filename="package://simulation_vvm/meshes/IntelRealsense_D435_Multibody.STL" scale="0.001 0.001 0.001"/>
      </geometry>
    </collision>
    <visual name="camera_link_visual">
      <origin xyz="0 0 0" rpy="0 0 0"/>
      <geometry>
        <!-- <box size="0.1 0.1 0.1"/> -->
        <mesh filename="package://simulation_vvm/meshes/IntelRealsense_D435_Multibody.STL" scale="0.001 0.001 0.001"/>
      </geometry>
    </visual>
  </link>

  <!-- Joint definitions -->
  <joint name="joint1" type="revolute">
    <parent link="link1"/>
    <child link="link2"/>
    <origin xyz="0.012 0 0.017" rpy="0 0 0"/>
    <axis xyz="0 0 1"/>
    <limit lower="-2.82743" upper="2.82743" effort="1" velocity="4.8"/>
    <dynamics damping="0" friction="0" />
  </joint>

  <joint name="joint2" type="revolute">
    <parent link="link2"/>
    <child link="link3"/>
    <origin xyz="0 0 0.0595" rpy="0 0 0"/>
    <axis xyz="0 1 0"/>
    <limit lower="-1.79071" upper="1.5708" effort="1" velocity="4.8"/>
    <dynamics damping="0" friction="0" />
  </joint>

  <joint name="joint3" type="revolute">
    <parent link="link3"/>
    <child link="link4"/>
    <origin xyz="0.024 0 0.128" rpy="0 0 0"/>
    <axis xyz="0 1 0"/>
    <limit lower="-0.942478" upper="1.3823" effort="1" velocity="4.8"/>
    <dynamics damping="0" friction="0" />
  </joint>

  <joint name="joint4" type="revolute">
    <parent link="link4"/>
    <child link="link5"/>
    <origin xyz="0.124 0 0" rpy="0 0 0"/>
    <axis xyz="0 1 0"/>
    <limit lower="-1.79071" upper="2.04204" effort="1" velocity="4.8"/>
    <dynamics damping="0" friction="0" />
  </joint>

  <joint name="gripper" type="prismatic">
    <parent link="link5"/>
    <child link="gripper_link"/>
    <origin xyz="0.0817 0.021 0" rpy="0 0 0"/>
    <axis xyz="0 1 0"/>
    <limit lower="-0.01" upper="0.019" effort="1" velocity="4.8"/>
    <dynamics damping="0" friction="0" />
  </joint>

  <joint name="gripper_sub" type="prismatic">
    <parent link="link5"/>
    <child link="gripper_link_sub"/>
    <origin xyz="0.0817 -0.021 0" rpy="0 0 0"/>
    <axis xyz="0 -1 0"/>
    <limit lower="-0.01" upper="0.019" effort="1" velocity="4.8"/>
    <dynamics damping="0" friction="0" />
  </joint>

  <joint name="camera_joint" type="fixed">
    <axis xyz="0 1 0" />
    <origin xyz="0.05 -0.045 0.065" rpy="-1.5708 0 1.5708"/> 
    <parent link="link5"/>
    <child link="camera_link"/>
  </joint>
</robot>
