<?xml version="1.0"?>
<robot
  name="VoiceVidManipulator" xmlns:xacro="http://ros.org/wiki/xacro">
  <link name='world'/>
  <joint name="dummy_joint" type="fixed">
    <parent link="world"/>
    <child link="link1"/>
  </joint>
  <link name="link1">
    <inertial>
      <origin xyz="0.000309 0 -0.000122" rpy="0 0 0"/>
      <mass value="0.07912"/>
      <inertia ixx="1.25052e-05" ixy="0" ixz="-1.78552e-07" iyy="2.18984e-05" iyz="0" izz="1.92674e-05"/>
    </inertial> 
    <collision name="link1_collision">
      <origin xyz="0 0 0" rpy="0 0 0"/>
      <geometry>
        <mesh filename="package://simulation_vvm/meshes/chain_link1.stl" scale="0.001 0.001 0.001"/>
      </geometry>
    </collision>
    <visual name="link1_visual">
      <origin xyz="0 0 0" rpy="0 0 0"/>
      <geometry>
        <mesh filename="package://simulation_vvm/meshes/chain_link1.stl" scale="0.001 0.001 0.001"/>
      </geometry>
    </visual>
  </link>

  <link name="link2">
    <inertial>
      <origin xyz="-0.000302 0.00054 0.047433" rpy="0 0 0"/>
      <mass value="0.0984068"/>
      <inertia ixx="3.45434e-05" ixy="-1.60311e-08" ixz="-3.83752e-07" iyy="3.26893e-05" iyz="2.85119e-08" izz="1.88503e-05"/>
    </inertial>
    <collision name="link2_collision">
      <origin xyz="0 0 0.019" rpy="0 0 0"/>
      <geometry>
        <mesh filename="package://simulation_vvm/meshes/chain_link2.stl" scale="0.001 0.001 0.001"/>
      </geometry>
    </collision>
    <visual name="link2_visual">
      <origin xyz="0 0 0.019" rpy="0 0 0"/>
      <geometry>
        <mesh filename="package://simulation_vvm/meshes/chain_link2.stl" scale="0.001 0.001 0.001"/>
      </geometry>
    </visual>
  </link>

  <link name="link3">
    <inertial>
      <origin xyz="0.010308 0.000377 0.101702" rpy="0 0 0"/>
      <mass value="0.138509"/>
      <inertia ixx="0.000330554" ixy="-9.7941e-08" ixz="-3.85057e-05" iyy="0.000342904" iyz="-1.57175e-06" izz="6.03465e-05"/>
    </inertial>
    <collision name="link3_collision">
      <origin xyz="0 0 0" rpy="0 0 0"/>
      <geometry>
        <mesh filename="package://simulation_vvm/meshes/chain_link3.stl" scale="0.001 0.001 0.001"/>
      </geometry>
    </collision>
    <visual name="link3_visual">
      <origin xyz="0 0 0" rpy="0 0 0"/>
      <geometry>
        <mesh filename="package://simulation_vvm/meshes/chain_link3.stl" scale="0.001 0.001 0.001"/>
      </geometry>
    </visual>
  </link>

  <link name="link4">
    <inertial>
      <origin xyz="0.09091 0.000389 0.000224" rpy="0 0 0"/>
      <mass value="0.132746"/>
      <inertia ixx="3.06542e-05" ixy="-1.27642e-06" ixz="-2.68744e-07" iyy="0.000242303" iyz="1.15595e-08" izz="0.000251551"/>
    </inertial>
    <collision name="link4_collision">
      <origin xyz="0 0 0" rpy="0 0 0"/>
      <geometry>
        <mesh filename="package://simulation_vvm/meshes/chain_link4.stl" scale="0.001 0.001 0.001"/>
      </geometry>
    </collision>
    <visual name="link4_visual">
      <origin xyz="0 0 0" rpy="0 0 0"/>
      <geometry>
        <mesh filename="package://simulation_vvm/meshes/chain_link4.stl" scale="0.001 0.001 0.001"/>
      </geometry>
    </visual>
  </link>

  <link name="link5">
    <inertial>
      <origin xyz="0.044774 0 0.008852" rpy="0 0 0"/>
      <mass value="0.144276"/>
      <inertia ixx="0.00108095" ixy="2.99238e-11" ixz="-2.9172e-07" iyy="0.0010827" iyz="-3.26124e-12" izz="0.00109977"/>
    </inertial>
    <collision name="link5_collision">
      <origin xyz="0 0 0" rpy="0 0 0"/>
      <geometry>
        <mesh filename="package://simulation_vvm/meshes/chain_link5.stl" scale="0.001 0.001 0.001"/>
      </geometry>
    </collision>
    <visual name="link5_visual">
      <origin xyz="0 0 0" rpy="0 0 0"/>
      <geometry>
        <mesh filename="package://simulation_vvm/meshes/chain_link5.stl" scale="0.001 0.001 0.001"/>
      </geometry>
    </visual>
    <!-- <visual name="link5_fixed_joint_lump__end_effector_link_visual_1"> -->
      <!-- <origin xyz="0.126 0 0" rpy="0 0 0"/> -->
      <!-- <geometry> -->
        <!-- <box size="0.01 0.01 0.01"/> -->
      <!-- </geometry> -->
    <!-- </visual> -->
  </link>

  <link name="gripper_link">
    <inertial>
      <origin xyz="0 0 0" rpy="0 0 0"/>
      <mass value="0.001"/>
      <inertia ixx="0.001" ixy="0" ixz="0" iyy="0.001" iyz="0" izz="0.001"/>
    </inertial>
    <collision name="gripper_link_collision">
      <origin xyz="0 0 0" rpy="0 0 0"/>
      <geometry>
        <mesh filename="package://simulation_vvm/meshes/chain_link_grip_l.stl" scale="0.001 0.001 0.001"/>
      </geometry>
    </collision>
    <visual name="gripper_link_visual">
      <origin xyz="0 0 0" rpy="0 0 0"/>
      <geometry>
        <mesh filename="package://simulation_vvm/meshes/chain_link_grip_l.stl" scale="0.001 0.001 0.001"/>
      </geometry>
    </visual>
  </link>

  <link name="gripper_link_sub">
    <inertial>
      <origin xyz="0 0 0" rpy="0 0 0"/>
      <mass value="0.001"/>
      <inertia ixx="0.001" ixy="0" ixz="0" iyy="0.001" iyz="0" izz="0.001"/>
    </inertial>
    <collision name="gripper_link_sub_collision">
      <origin xyz="0 0 0" rpy="0 0 0"/>
      <geometry>
        <mesh filename="package://simulation_vvm/meshes/chain_link_grip_r.stl" scale="0.001 0.001 0.001"/>
      </geometry>
    </collision>
    <visual name="gripper_link_sub_visual">
      <origin xyz="0 0 0" rpy="0 0 0"/>
      <geometry>
        <mesh filename="package://simulation_vvm/meshes/chain_link_grip_r.stl" scale="0.001 0.001 0.001"/>
      </geometry>
    </visual>
  </link>

  <link name="camera_link">
    <inertial>
      <origin xyz="0 0 0" rpy="0 0 1.5708"/>
      <mass value="0.001"/>
      <inertia ixx="0.001" ixy="0" ixz="0" iyy="0.001" iyz="0" izz="0.001"/>
    </inertial>
    <collision name="camera_link_collision">
      <origin xyz="0 0 0" rpy="0 0 0"/>
      <geometry>
        <mesh filename="package://simulation_vvm/meshes/IntelRealsense_D435_Multibody.STL" scale="0.001 0.001 0.001"/>
      </geometry>
    </collision>
    <visual name="camera_link_visual">
      <origin xyz="0 0 0" rpy="0 0 0"/>
      <geometry>
        <mesh filename="package://simulation_vvm/meshes/IntelRealsense_D435_Multibody.STL" scale="0.001 0.001 0.001"/>
      </geometry>
    </visual>
  </link>
  <link name="camera_frame_link">
    <!-- <inertial>
      <origin xyz="0 0 0" rpy="0 0 0"/>
      <mass value="0.001"/>
      <inertia ixx="0.001" ixy="0" ixz="0" iyy="0.001" iyz="0" izz="0.001"/>
    </inertial> -->
  </link>

  <!-- Joint definitions -->
  <joint name="joint1" type="revolute">
    <parent link="link1"/>
    <child link="link2"/>
    <origin xyz="0.012 0 0.017" rpy="0 0 0"/>
    <axis xyz="0 0 1"/>
    <limit lower="-2.82743" upper="2.82743" effort="1" velocity="4.8"/>
    <dynamics damping="0" friction="0" />
  </joint>

  <joint name="joint2" type="revolute">
    <parent link="link2"/>
    <child link="link3"/>
    <origin xyz="0 0 0.0595" rpy="0 0 0"/>
    <axis xyz="0 1 0"/>
    <limit lower="-1.79071" upper="1.5708" effort="1" velocity="4.8"/>
    <dynamics damping="0" friction="0" />
  </joint>

  <joint name="joint3" type="revolute">
    <parent link="link3"/>
    <child link="link4"/>
    <origin xyz="0.024 0 0.128" rpy="0 0 0"/>
    <axis xyz="0 1 0"/>
    <limit lower="-0.942478" upper="1.3823" effort="1" velocity="4.8"/>
    <dynamics damping="0" friction="0" />
  </joint>

  <joint name="joint4" type="revolute">
    <parent link="link4"/>
    <child link="link5"/>
    <origin xyz="0.124 0 0" rpy="0 0 0"/>
    <axis xyz="0 1 0"/>
    <limit lower="-1.79071" upper="2.04204" effort="1" velocity="4.8"/>
    <dynamics damping="0" friction="0" />
  </joint>

  <joint name="gripper" type="prismatic">
    <parent link="link5"/>
    <child link="gripper_link"/>
    <origin xyz="0.0817 0.021 0" rpy="0 0 0"/>
    <axis xyz="0 1 0"/>
    <limit lower="-0.01" upper="0.019" effort="1" velocity="4.8"/>
    <dynamics damping="0" friction="0" />
  </joint>

  <joint name="gripper_sub" type="prismatic">
    <parent link="link5"/>
    <child link="gripper_link_sub"/>
    <origin xyz="0.0817 -0.021 0" rpy="0 0 0"/>
    <axis xyz="0 -1 0"/>
    <limit lower="-0.01" upper="0.019" effort="1" velocity="4.8"/>
    <dynamics damping="0" friction="0" />
  </joint>

  <joint name="camera_joint" type="fixed">
    <axis xyz="0 1 0" />
    <origin xyz="0.05 -0.045 0.065" rpy="-1.5708 0 1.5708"/> 
    <parent link="link5"/>
    <child link="camera_link"/>
  </joint>

  <joint name="camera_to_camera_frame_joint" type="fixed">
    <origin xyz="0.045 0.012 0" rpy="0 1.5708 0"/> 
    <parent link="camera_link"/>
    <child link="camera_frame_link"/>
  </joint>
  


  <ros2_control name="GazeboSystem" type="system">
    <hardware>
      <plugin>gazebo_ros2_control/GazeboSystem</plugin>
    </hardware>
    <joint name="joint1">
      <command_interface name="position"/>
      <state_interface name="position">
        <param name="initial_value">0.0</param>
      </state_interface>
      <state_interface name="velocity"/>
      <state_interface name="effort"/>
    </joint>
    <joint name="joint2">
      <command_interface name="position"/>
      <state_interface name="position">
        <param name="initial_value">0.0</param>
      </state_interface>
      <state_interface name="velocity"/>
      <state_interface name="effort"/>
    </joint>
    <joint name="joint3">
      <command_interface name="position"/>
      <state_interface name="position">
        <param name="initial_value">0.0</param>
      </state_interface>
      <state_interface name="velocity"/>
      <state_interface name="effort"/>
    </joint>
    <joint name="joint4">
      <command_interface name="position"/>
      <state_interface name="position">
        <param name="initial_value">0.0</param>
      </state_interface>
      <state_interface name="velocity"/>
      <state_interface name="effort"/>
    </joint>
    <joint name="gripper">
      <command_interface name="position"/>
      <state_interface name="position">
        <param name="initial_value">0.0</param>
      </state_interface>
      <state_interface name="velocity"/>
      <state_interface name="effort"/>
    </joint>
    <joint name="gripper_sub">
      <command_interface name="position"/>
      <state_interface name="position">
        <param name="initial_value">0.0</param>
      </state_interface>
      <state_interface name="velocity"/>
      <state_interface name="effort"/>
    </joint>
  </ros2_control>

  <gazebo reference= 'camera_frame_link'>
    <sensor name="camera" type="camera">
      <pose> 0 0 0 0 0 0 </pose>
      <visualize>true</visualize>
      <update_rate>10</update_rate>
      <camera>
          <horizontal_fov>1.089</horizontal_fov>
          <image>
              <format>R8G8B8</format>
              <width>640</width>
              <height>480</height>
          </image>
          <clip>
              <near>0.05</near>
              <far>8.0</far>
          </clip>
      </camera>
      <plugin name="camera_controller" filename="libgazebo_ros_camera.so">
        <frame_name>camera_frame_link</frame_name>
        <alwaysOn>true</alwaysOn>
        <updateRate>0.0</updateRate>
        <cameraName>camera</cameraName>
        <imageTopicName>image_raw</imageTopicName>
        <cameraInfoTopicName>camera_info</cameraInfoTopicName>
        <!-- <hackBaseline>0.07</hackBaseline> -->
        <distortionK1>0.0</distortionK1>
        <distortionK2>0.0</distortionK2>
        <distortionK3>0.0</distortionK3>
        <distortionT1>0.0</distortionT1>
        <distortionT2>0.0</distortionT2>
      </plugin>
    </sensor>
  </gazebo>

    <!-- librealsense_gazebo_plugin.so -->
  <!-- <gazebo>
    <plugin name="camera_controller" filename="libDepthCameraPlugin.so">
      <prefix>Intel_Depth_Camera</prefix>
      <depthUpdateRate>30.0</depthUpdateRate>
      <colorUpdateRate>30.0</colorUpdateRate>
      <infraredUpdateRate>30.0</infraredUpdateRate>
      <depthTopicName>depth/image_raw</depthTopicName>
      <depthCameraInfoTopicName>depth/camera_info</depthCameraInfoTopicName>
      <colorTopicName>color/image_raw</colorTopicName>
      <colorCameraInfoTopicName>color/camera_info</colorCameraInfoTopicName>
      <infrared1TopicName>infra1/image_raw</infrared1TopicName>
      <infrared1CameraInfoTopicName>infra1/camera_info</infrared1CameraInfoTopicName>
      <infrared2TopicName>infra2/image_raw</infrared2TopicName>
      <infrared2CameraInfoTopicName>infra2/camera_info</infrared2CameraInfoTopicName>
      <colorOpticalframeName>${color_optical_frame}</colorOpticalframeName>
      <depthOpticalframeName>${depth_optical_frame}</depthOpticalframeName>
      <infrared1OpticalframeName>${infrared1_optical_frame}</infrared1OpticalframeName>
      <infrared2OpticalframeName>${infrared2_optical_frame}</infrared2OpticalframeName>
      <rangeMinDepth>0.2</rangeMinDepth>
      <rangeMaxDepth>10.0</rangeMaxDepth>
      <pointCloud>${publish_pointcloud}</pointCloud>
      <pointCloudTopicName>depth/color/points</pointCloudTopicName>
      <pointCloudCutoff>0.25</pointCloudCutoff>
      <pointCloudCutoffMax>9.0</pointCloudCutoffMax>
    </plugin>
  </gazebo> -->
  
  <gazebo>
    <plugin filename="libgazebo_ros2_control.so" name="gazebo_ros2_control"> 
      <parameters>$(find simulation_vvm)/config/vvm.yaml</parameters>
      <robot_param>robot_description</robot_param>
      <robot_param_node>robot_state_publisher</robot_param_node>
      <controller_manager_name>controller_manager</controller_manager_name>
    </plugin>
  </gazebo>
</robot>